Workbook

Sheet Petunjuk
B2: QC Manual Testing Checklist - Harmoni Clothing
B3: Daftar SELURUH halaman, fitur, alur, aturan bisnis, halaman error, validasi, keamanan, dan integrasi untuk pengujian manual sebelum rilis. Versi: 2026-10-13.
B5: Ringkasan progres (otomatis)
B6: Sheet | C6: Halaman/Fitur | D6: Poin | E6: Lulus | F6: Gagal | G6: N-A | H6: Belum Diuji | I6: % Selesai
B7: Public (Pengunjung) | C7: =COUNTA('Public (Pengunjung)'!C2:C180) | D7: =COUNTA('Public (Pengunjung)'!F2:F180) | E7: =COUNTIF('Public (Pengunjung)'!G2:G180,"Lulus") | F7: =COUNTIF('Public (Pengunjung)'!G2:G180,"Gagal") | G7: =COUNTIF('Public (Pengunjung)'!G2:G180,"N-A") | H7: =COUNTIF('Public (Pengunjung)'!G2:G180,"Belum Diuji") | I7: =IF(D7=0,0,(E7+F7+G7)/D7)
B8: Customer (Sudah Login) | C8: =COUNTA('Customer (Sudah Login)'!C2:C136) | D8: =COUNTA('Customer (Sudah Login)'!F2:F136) | E8: =COUNTIF('Customer (Sudah Login)'!G2:G136,"Lulus") | F8: =COUNTIF('Customer (Sudah Login)'!G2:G136,"Gagal") | G8: =COUNTIF('Customer (Sudah Login)'!G2:G136,"N-A") | H8: =COUNTIF('Customer (Sudah Login)'!G2:G136,"Belum Diuji") | I8: =IF(D8=0,0,(E8+F8+G8)/D8)
B9: Creator | C9: =COUNTA('Creator'!C2:C52) | D9: =COUNTA('Creator'!F2:F52) | E9: =COUNTIF('Creator'!G2:G52,"Lulus") | F9: =COUNTIF('Creator'!G2:G52,"Gagal") | G9: =COUNTIF('Creator'!G2:G52,"N-A") | H9: =COUNTIF('Creator'!G2:G52,"Belum Diuji") | I9: =IF(D9=0,0,(E9+F9+G9)/D9)
B10: Admin | C10: =COUNTA('Admin'!C2:C101) | D10: =COUNTA('Admin'!F2:F101) | E10: =COUNTIF('Admin'!G2:G101,"Lulus") | F10: =COUNTIF('Admin'!G2:G101,"Gagal") | G10: =COUNTIF('Admin'!G2:G101,"N-A") | H10: =COUNTIF('Admin'!G2:G101,"Belum Diuji") | I10: =IF(D10=0,0,(E10+F10+G10)/D10)
B11: Fitur Lintas Halaman (Umum) | C11: =COUNTA('Fitur Lintas Halaman (Umum)'!C2:C62) | D11: =COUNTA('Fitur Lintas Halaman (Umum)'!F2:F62) | E11: =COUNTIF('Fitur Lintas Halaman (Umum)'!G2:G62,"Lulus") | F11: =COUNTIF('Fitur Lintas Halaman (Umum)'!G2:G62,"Gagal") | G11: =COUNTIF('Fitur Lintas Halaman (Umum)'!G2:G62,"N-A") | H11: =COUNTIF('Fitur Lintas Halaman (Umum)'!G2:G62,"Belum Diuji") | I11: =IF(D11=0,0,(E11+F11+G11)/D11)
B12: Halaman Error & Edge | C12: =COUNTA('Halaman Error & Edge'!C2:C56) | D12: =COUNTA('Halaman Error & Edge'!F2:F56) | E12: =COUNTIF('Halaman Error & Edge'!G2:G56,"Lulus") | F12: =COUNTIF('Halaman Error & Edge'!G2:G56,"Gagal") | G12: =COUNTIF('Halaman Error & Edge'!G2:G56,"N-A") | H12: =COUNTIF('Halaman Error & Edge'!G2:G56,"Belum Diuji") | I12: =IF(D12=0,0,(E12+F12+G12)/D12)
B13: Validasi Form & API | C13: =COUNTA('Validasi Form & API'!C2:C50) | D13: =COUNTA('Validasi Form & API'!F2:F50) | E13: =COUNTIF('Validasi Form & API'!G2:G50,"Lulus") | F13: =COUNTIF('Validasi Form & API'!G2:G50,"Gagal") | G13: =COUNTIF('Validasi Form & API'!G2:G50,"N-A") | H13: =COUNTIF('Validasi Form & API'!G2:G50,"Belum Diuji") | I13: =IF(D13=0,0,(E13+F13+G13)/D13)
B14: Aturan Bisnis (BR) | C14: =COUNTA('Aturan Bisnis (BR)'!C2:C39) | D14: =COUNTA('Aturan Bisnis (BR)'!F2:F39) | E14: =COUNTIF('Aturan Bisnis (BR)'!G2:G39,"Lulus") | F14: =COUNTIF('Aturan Bisnis (BR)'!G2:G39,"Gagal") | G14: =COUNTIF('Aturan Bisnis (BR)'!G2:G39,"N-A") | H14: =COUNTIF('Aturan Bisnis (BR)'!G2:G39,"Belum Diuji") | I14: =IF(D14=0,0,(E14+F14+G14)/D14)
B15: Alur End-to-End | C15: =COUNTA('Alur End-to-End'!C2:C65) | D15: =COUNTA('Alur End-to-End'!F2:F65) | E15: =COUNTIF('Alur End-to-End'!G2:G65,"Lulus") | F15: =COUNTIF('Alur End-to-End'!G2:G65,"Gagal") | G15: =COUNTIF('Alur End-to-End'!G2:G65,"N-A") | H15: =COUNTIF('Alur End-to-End'!G2:G65,"Belum Diuji") | I15: =IF(D15=0,0,(E15+F15+G15)/D15)
B16: Backend, Job & Email | C16: =COUNTA('Backend, Job & Email'!C2:C69) | D16: =COUNTA('Backend, Job & Email'!F2:F69) | E16: =COUNTIF('Backend, Job & Email'!G2:G69,"Lulus") | F16: =COUNTIF('Backend, Job & Email'!G2:G69,"Gagal") | G16: =COUNTIF('Backend, Job & Email'!G2:G69,"N-A") | H16: =COUNTIF('Backend, Job & Email'!G2:G69,"Belum Diuji") | I16: =IF(D16=0,0,(E16+F16+G16)/D16)
B17: Keamanan | C17: =COUNTA('Keamanan'!C2:C41) | D17: =COUNTA('Keamanan'!F2:F41) | E17: =COUNTIF('Keamanan'!G2:G41,"Lulus") | F17: =COUNTIF('Keamanan'!G2:G41,"Gagal") | G17: =COUNTIF('Keamanan'!G2:G41,"N-A") | H17: =COUNTIF('Keamanan'!G2:G41,"Belum Diuji") | I17: =IF(D17=0,0,(E17+F17+G17)/D17)
B18: TOTAL | C18: =SUM(C7:C17) | D18: =SUM(D7:D17) | E18: =SUM(E7:E17) | F18: =SUM(F7:F17) | G18: =SUM(G7:G17) | H18: =SUM(H7:H17) | I18: =IF(D18=0,0,(E18+F18+G18)/D18)
B19: Kolom "Gagal" > 0 menandakan bug yang harus ditindaklanjuti sebelum rilis. Angka diperbarui otomatis dari kolom Hasil tiap sheet.
B21: Isi workbook
B22: Public (Pengunjung) | C22: Semua halaman & modal untuk guest: beranda, katalog, marketplace, info, legal, auth, SEO.
B23: Customer (Sudah Login) | C23: Keranjang, checkout, bulk order, pesanan, invoice, profil, alamat, wishlist, notifikasi, chat.
B24: Creator | C24: Area creator: KYC, desain, upload, komisi.
B25: Admin | C25: Semua halaman admin termasuk approval, blokir creator, katalog, tier Bulk, produksi, pengiriman.
B26: Fitur Lintas Halaman (Umum) | C26: Role access, bahasa, responsif, browser, aksesibilitas, upload, Midtrans, Biteship.
B27: Halaman Error & Edge | C27: 404, error boundary, backend mati, sesi habis, kode status, state kosong/loading, edge data.
B28: Validasi Form & API | C28: Batas validasi setiap form & parameter (min/maks/format) sesuai Form Request.
B29: Aturan Bisnis (BR) | C29: Verifikasi tiap Business Rule BR-001–028.
B30: Alur End-to-End | C30: Skenario lintas peran dari awal sampai akhir (golden path & jalur pengecualian).
B31: Backend, Job & Email | C31: Scheduler, webhook, kontrak API, email, realtime, storage, deploy, tes otomatis.
B32: Keamanan | C32: Auth, IDOR, XSS/SQLi, CSRF/CORS, upload, rahasia, privasi.
B34: Persiapan sebelum menguji
B35: Akun uji | C35: Siapkan akun Customer, Creator (aktif), Creator (menunggu approval), dan Admin (lihat seeder / README). Siapkan juga 1 akun baru untuk uji registrasi & verifikasi email.
B36: Dua browser | C36: Pakai dua browser/profil berbeda (mis. Chrome + Firefox) untuk uji real-time chat & notifikasi customer ↔ admin.
B37: Midtrans Sandbox | C37: Kartu uji: 4811 1111 1111 1114, kedaluwarsa bebas di masa depan, CVV 123, OTP 3DS 112233. Gunakan VA/e-wallet simulator Midtrans untuk metode lain.
B38: Biteship | C38: Gunakan alamat dengan kode pos nyata (mis. Jakarta Pusat 10110) agar kurir tersedia. Untuk webhook, kirim payload uji dengan token yang benar.
B39: Backend hidup | C39: Pastikan MySQL, backend (:8000) dan tunnel/Reverb menyala; tanpa itu seluruh API mengembalikan 502/500 (juga bagian dari uji di sheet Error).
B40: Job terjadwal | C40: Jalankan manual: php artisan orders:cancel-unpaid, orders:auto-complete-deliveries, commissions:payout (atau schedule:work).
B41: Data uji | C41: Pakai data uji, bukan data pelanggan nyata. Beberapa aksi (blokir creator) bersifat final lewat aplikasi — lakukan pada akun uji.
B43: Cara mengisi
B44: 1. | C44: Buka tiap sheet sesuai area. Setiap baris adalah satu poin yang harus dicek.
B45: 2. | C45: Isi kolom "Hasil" dari dropdown: Lulus / Gagal / Belum Diuji / N-A.
...

Sheet Public (Pengunjung)
A1: No | B1: Modul | C1: Halaman / Fitur | D1: URL / Path | E1: Deskripsi Halaman/Fitur | F1: Poin yang Diuji | G1: Hasil | H1: Catatan Tester
A2: 1 | B2: Public (Pengunjung) | C2: Beranda (Landing Page) | D2: / | E2: Halaman utama publik: hero, 4 lencana kepercayaan, cara kerja, produk & desain populer, testimoni, CTA. | F2: Hero tampil lengkap: 3 baris headline, subjudul, ilustrasi (hoodie & kaos), kartu "Custom by You" | G2: Belum Diuji
A3: 2 | F3: Tombol "Mulai Custom Design" & "Jelajahi Produk" di hero mengarah ke halaman yang benar | G3: Belum Diuji
A4: 3 | F4: 4 lencana kepercayaan (Tanpa Minimum Order, Kualitas Premium, Produksi Cepat, Garansi Kepuasan) tampil lengkap & teksnya benar | G4: Belum Diuji
A5: 4 | F5: Section "Cara Kerja": 4 langkah (Pilih Produk, Buat Desain, Konfirmasi Pesanan, Terima Produk) tampil berurutan | G5: Belum Diuji
A6: 5 | F6: "Produk Populer" menampilkan produk nyata (gambar, nama, harga "Mulai dari Rp...", jumlah terjual) | G6: Belum Diuji
A7: 6 | F7: Link "Lihat Semua Produk →" membuka /catalog; klik kartu produk membuka detail produk yang benar | G7: Belum Diuji
A8: 7 | F8: "Desain Populer" menampilkan desain nyata (thumbnail, nama desain, nama creator, harga) | G8: Belum Diuji
A9: 8 | F9: Link "Lihat Semua Desain →" membuka /marketplace; klik kartu desain membuka detail desain yang benar | G9: Belum Diuji
A10: 9 | F10: Testimoni (marquee) berjalan otomatis, mulus tanpa patah/melompat, semua 8 testimoni terbaca | G10: Belum Diuji
A11: 10 | F11: Section CTA bawah: tombol "Mulai Custom Design" & "Daftar Gratis" (membuka modal registrasi) berfungsi | G11: Belum Diuji
A12: 11 | F12: Saat data produk/desain sedang dimuat tampil skeleton/loading, bukan layar kosong | G12: Belum Diuji
A13: 12 | F13: Jika data produk/desain kosong atau API gagal, section menampilkan empty/error state (bukan crash) | G13: Belum Diuji
A14: 13 | F14: Animasi muncul (Reveal) saat scroll berjalan; tidak ada konten yang tetap tersembunyi/terpotong | G14: Belum Diuji
... A17: 16 | F17: Tampilan rapi di mobile (375px), tablet (768px), dan desktop (1280px+) | G17: Belum Diuji
A18: 17 | B18: Public (Pengunjung) | C18: Header / Navbar (Guest) | D18: Semua halaman publik | E18: Navigasi utama untuk pengunjung yang belum login. | F18: Logo mengarah ke beranda | G18: Belum Diuji
A19: 18 | F19: Menu Beranda, Produk, Desain, Tentang Kami mengarah ke halaman yang benar; menu aktif ter-highlight | G19: Belum Diuji
A20: 19 | F20: Tombol "Masuk" membuka modal login; "Daftar Gratis" membuka modal registrasi | G20: Belum Diuji
A21: 20 | F21: Ikon keranjang untuk guest: perilaku sesuai (login dulu / keranjang kosong) dan tidak error | G21: Belum Diuji
A22: 21 | F22: Saklar bahasa ID/EN tampil dan berfungsi | G22: Belum Diuji
A23: 22 | F23: Di mobile: ikon hamburger membuka drawer menu, tombol tutup menutup, menu dalam drawer berfungsi | G23: Belum Diuji
A24: 23 | F24: Header tidak berkedip (flicker) saat pertama kali dimuat / saat status login ditentukan | G24: Belum Diuji
A25: 24 | B25: Public (Pengunjung) | C25: Footer | D25: Semua halaman publik | E25: Footer situs: tautan produk, bantuan, kebijakan, hak cipta, saklar bahasa. | F25: Tautan PRODUK (T-Shirt, Hoodie, Jacket) mengarah ke katalog dengan filter yang benar | G25: Belum Diuji
A26: 25 | F26: Tautan BANTUAN (FAQ, Pusat Bantuan, Kontak) membuka halaman yang benar | G26: Belum Diuji
A27: 26 | F27: Tautan KEBIJAKAN (Syarat & Ketentuan, Kebijakan Privasi, Retur & Refund, Pengiriman) membuka halaman yang benar | G27: Belum Diuji
A28: 27 | F28: Teks hak cipta menampilkan tahun yang benar | G28: Belum Diuji
A29: 28 | F29: Saklar bahasa di footer berfungsi & sinkron dengan saklar di header | G29: Belum Diuji
A30: 29 | F30: Tidak ada tautan mati (404) di footer | G30: Belum Diuji
A31: 30 | B31: Public (Pengunjung) | C31: Marketplace Desain (Tab Desain) | D31: /marketplace | E31: Jelajah & cari desain siap pakai dari para creator. | F31: Grid desain menampilkan data nyata (thumbnail, nama desain, nama creator, harga, terjual) | G31: Belum Diuji
A32: 31 | F32: Search bar mencari berdasarkan nama desain/tag; tombol "Hapus pencarian" mengosongkan kata kunci | G32: Belum Diuji
A33: 32 | F33: Filter kategori, tag, dan rentang harga (min/maks) mengubah hasil sesuai pilihan | G33: Belum Diuji
A34: 33 | F34: Tombol naik/turun harga minimum & maksimum bekerja; min tidak boleh melebihi maks | G34: Belum Diuji
A35: 34 | F35: Urutkan: Terbaru, Harga Rendah→Tinggi, Harga Tinggi→Rendah, Terlaris, Rating Tertinggi — hasil sesuai | G35: Belum Diuji
A36: 35 | F36: Teks "Menampilkan X dari Y desain" sesuai jumlah sebenarnya | G36: Belum Diuji
A37: 36 | F37: Tombol "Muat Lebih Banyak" memuat halaman berikutnya, hilang saat semua desain sudah tampil | G37: Belum Diuji
A38: 37 | F38: Kombinasi filter + pencarian + urutan bekerja bersamaan; "Reset pencarian & filter" mengembalikan semua | G38: Belum Diuji
A39: 38 | F39: Hasil kosong menampilkan pesan "Belum ada desain ditemukan untuk filter ini" + tombol reset | G39: Belum Diuji
A40: 39 | F40: State filter tersimpan di URL (query string): refresh/bagikan URL menghasilkan hasil yang sama | G40: Belum Diuji
A41: 40 | F41: Klik kartu desain membuka Detail Desain yang benar | G41: Belum Diuji
A42: 41 | F42: Ikon wishlist (love) pada kartu: guest diminta login; user login bisa menambah/menghapus | G42: Belum Diuji
...

Sheet Customer (Sudah Login)
A1: No | B1: Modul | C1: Halaman / Fitur | D1: URL / Path | E1: Deskripsi Halaman/Fitur | F1: Poin yang Diuji | G1: Hasil | H1: Catatan Tester
A2: 1 | B2: Customer (Sudah Login) | C2: Header (Customer Login) | D2: Semua halaman | E2: Header setelah login: avatar, menu akun, keranjang, notifikasi, tombol Kreator. | F2: Avatar/foto & nama user tampil; menu dropdown akun terbuka/tertutup (klik luar menutup) | G2: Belum Diuji
A3: 2 | F3: Menu akun: Kelola Profil, Address Book, Wishlist, Keranjang, Riwayat Pesanan, Ajukan Upgrade Creator, Notifikasi, Keluar — semua mengarah benar | G3: Belum Diuji
A4: 3 | F4: Untuk akun creator: tombol "Kreator" mengarah ke /creator/dashboard; akun customer biasa menampilkan versi yang sesuai | G4: Belum Diuji
A5: 4 | F5: Untuk admin: menu "Admin Dashboard" tampil & berfungsi | G5: Belum Diuji
A6: 5 | F6: Logout menampilkan dialog konfirmasi "Apakah Anda yakin ingin keluar?"; Batal tetap login; Konfirmasi keluar & ke beranda | G6: Belum Diuji
A7: 6 | F7: Setelah logout, tombol Back browser tidak menampilkan data akun sebelumnya | G7: Belum Diuji
A8: 7 | F8: Header tidak berkedip/"flash" status guest saat memuat halaman atau ganti bahasa | G8: Belum Diuji
A9: 8 | B9: Customer (Sudah Login) | C9: Dropdown Keranjang (Header) | D9: Header semua halaman | E9: Pratinjau keranjang dari header. | F9: Badge jumlah item benar & ter-update tanpa refresh saat tambah/hapus item | G9: Belum Diuji
A10: 9 | F10: Popover menampilkan item terbaru (gambar, nama, varian, qty, harga) & subtotal benar | G10: Belum Diuji
A11: 10 | F11: Keranjang kosong menampilkan "Keranjangmu masih kosong" | G11: Belum Diuji
A12: 11 | F12: Tombol "Lanjut ke Checkout" membuka /cart atau /checkout yang benar | G12: Belum Diuji
A13: 12 | F13: Klik di luar popover menutupnya; di mobile tetap dapat dipakai | G13: Belum Diuji
A14: 13 | B14: Customer (Sudah Login) | C14: Dropdown Notifikasi (Header) | D14: Header semua halaman | E14: Pratinjau notifikasi dari header. | F14: Badge jumlah belum dibaca benar; ter-update real-time saat notifikasi baru masuk (tanpa refresh) | G14: Belum Diuji
A15: 14 | F15: Popover menampilkan notifikasi terbaru; kosong → "Belum ada notifikasi" | G15: Belum Diuji
A16: 15 | F16: "Tandai semua dibaca" mengosongkan badge & mengubah tampilan item | G16: Belum Diuji
A17: 16 | F17: Klik satu notifikasi menandainya dibaca & mengarah ke halaman terkait | G17: Belum Diuji
A18: 17 | B18: Customer (Sudah Login) | C18: Customize / Product Editor | D18: /customize/[slug] | E18: Kustomisasi produk (mode custom dengan upload sendiri, atau mode marketplace dengan desain terpilih). Catatan: editor 3D ditunda ke v1.1 — halaman ini berupa form 2D. | F18: Halaman termuat dengan produk yang benar; slug salah → pesan "tidak ditemukan" (bukan crash) | G18: Belum Diuji
A19: 18 | F19: Pilih warna & ukuran mengubah gambar mockup & harga; chip ukuran terpilih tampak aktif (ter-highlight) | G19: Belum Diuji
A20: 19 | F20: Tombol tampilan Depan/Belakang/Samping berfungsi atau berperilaku sesuai spesifikasi | G20: Belum Diuji
A21: 20 | F21: Mode Custom: upload desain sendiri (PNG/SVG ≤ 20MB (teks UI menyebut PNG/SVG; file JPG ditolak dengan pesan jelas)) berhasil; file salah format/terlalu besar ditolak | G21: Belum Diuji
A22: 21 | F22: Mode Marketplace (?design=...): desain terpilih tampil benar (nama, creator, thumbnail); "Ganti Desain" berfungsi | G22: Belum Diuji
A23: 22 | F23: Rincian harga (Harga Produk / Kontribusi Desainer / Total) terhitung benar sesuai qty | G23: Belum Diuji
A24: 23 | F24: Quantity stepper berfungsi (min 1); catatan opsional tersimpan | G24: Belum Diuji
A25: 24 | F25: "Tambah ke Keranjang" tanpa pilih varian → pesan error; sukses → toast & badge keranjang bertambah | G25: Belum Diuji
A26: 25 | F26: Catatan di halaman bahwa ini preview 2D (bukan 3D real-time) tidak menyesatkan pengguna | G26: Belum Diuji
A27: 26 | F27: Guest yang membuka halaman ini diarahkan/di-prompt login | G27: Belum Diuji
A28: 27 | B28: Customer (Sudah Login) | C28: Keranjang (Cart) | D28: /cart | E28: Melihat & mengelola item yang akan dibeli. | F28: Semua item tampil benar (gambar, nama, varian warna/ukuran, desain, catatan, qty, harga satuan, subtotal) | G28: Belum Diuji
A29: 28 | F29: Ubah qty (+/−) memperbarui subtotal & total; qty minimum 1 | G29: Belum Diuji
A30: 29 | F30: Hapus item berfungsi; keranjang kosong menampilkan state kosong + tombol "Mulai Belanja" | G30: Belum Diuji
A31: 30 | F31: Centang item per baris & "Pilih Semua (n)" berfungsi; total hanya menghitung item terpilih | G31: Belum Diuji
A32: 31 | F32: Tombol "Pindahkan ke wishlist" memindahkan item & menampilkan toast | G32: Belum Diuji
A33: 32 | F33: Item yang produknya sudah nonaktif ditandai "Produk ini sudah tidak tersedia" & tidak bisa di-checkout | G33: Belum Diuji
A34: 33 | F34: Harga item mengikuti harga saat ditambahkan ke keranjang (BR-025), bukan harga terbaru bila admin mengubah harga | G34: Belum Diuji
A35: 34 | F35: Tombol "Beli" tanpa item terpilih tidak aktif; dengan item terpilih membuka /checkout (tidak macet/loading terus) | G35: Belum Diuji
A36: 35 | F36: Tidak ada infinite re-render / lag saat memilih item (regresi bug lama) | G36: Belum Diuji
A37: 36 | F37: Setelah checkout berhasil, item yang dibeli hilang dari keranjang; item yang tidak dipilih tetap ada | G37: Belum Diuji
A38: 37 | F38: Keranjang tetap tersimpan setelah logout-login & lintas perangkat | G38: Belum Diuji
A39: 38 | F39: Format Rupiah benar di semua angka | G39: Belum Diuji
A40: 39 | B40: Customer (Sudah Login) | C40: Checkout (Reguler) | D40: /checkout | E40: Menyelesaikan pemesanan reguler: alamat, kurir, ringkasan, pembayaran. | F40: Mengakses /checkout tanpa item terpilih diarahkan kembali ke keranjang (tidak crash) | G40: Belum Diuji
...

Sheet Creator
A1: No | B1: Modul | C1: Halaman / Fitur | D1: URL / Path | E1: Deskripsi Halaman/Fitur | F1: Poin yang Diuji | G1: Hasil | H1: Catatan Tester
A2: 1 | B2: Creator | C2: Sidebar & Akses Area Creator | D2: /creator/* | E2: Navigasi area creator & pembatasan akses. | F2: Sidebar: Dashboard, Verifikasi Data Diri, Kelola Desain, Upload Desain, Statistik & Komisi — semua mengarah benar & item aktif ter-highlight | G2: Belum Diuji
A3: 2 | F3: Di mobile sidebar menjadi drawer/off-canvas yang dapat dibuka-tutup (bukan kolom sempit) | G3: Belum Diuji
A4: 3 | F4: Customer biasa (belum creator) membuka /creator/* ditolak/diarahkan (CreatorGuard + middleware server) | G4: Belum Diuji
A5: 4 | F5: Creator yang BELUM disetujui (menunggu approval) hanya bisa mengakses halaman verifikasi, bukan upload/earnings | G5: Belum Diuji
A6: 5 | F6: Creator yang di-ban tidak bisa lagi mengakses fitur creator (API 403) | G6: Belum Diuji
A7: 6 | F7: Guest membuka /creator/* diarahkan ke login | G7: Belum Diuji
A8: 7 | F8: Pindah antara area Customer ↔ Creator tanpa logout; sesi tetap | G8: Belum Diuji
A9: 8 | B9: Creator | C9: Dashboard Creator | D9: /creator/dashboard | E9: Ringkasan performa creator. | F9: Kartu Total Desain, Desain Aktif, Menunggu Approval sesuai data nyata (label & nilai tidak tertukar) | G9: Belum Diuji
A10: 9 | F10: "Desain Terbaru" menampilkan daftar terbaru dengan thumbnail & status benar; "Lihat Semua" ke Kelola Desain | G10: Belum Diuji
A11: 10 | F11: Belum ada desain → pesan "Belum ada desain. Yuk upload desain pertamamu" | G11: Belum Diuji
A12: 11 | F12: Loading skeleton & error state tampil sesuai kondisi | G12: Belum Diuji
A13: 12 | B13: Creator | C13: Verifikasi Data Diri (KYC) | D13: /creator/verification | E13: Form KYC & data pencairan untuk aktivasi creator (BR-008). | F13: Form: Nama Lengkap (sesuai KTP), Nomor KTP, Tanggal Lahir, Alamat Lengkap (≤500), Foto KTP, Metode Pencairan, Nomor Rekening/HP, Nama Pemilik | G13: Belum Diuji
A14: 13 | F14: Semua field wajib; kosong ditolak dengan pesan per-field | G14: Belum Diuji
A15: 14 | F15: Tanggal lahir harus sebelum hari ini; tanggal masa depan ditolak | G15: Belum Diuji
A16: 15 | F16: Upload foto KTP: hanya JPG/PNG ≤ 5MB; format lain/ukuran besar ditolak; tanpa foto → "Unggah foto KTP terlebih dahulu" | G16: Belum Diuji
A17: 16 | F17: Metode pencairan: Transfer Bank, GoPay, OVO, DANA, ShopeePay — nilai di luar daftar ditolak | G17: Belum Diuji
A18: 17 | F18: Pengguna di bawah 18 tahun: muncul pemberitahuan + field Nama Wali, Nomor KTP Wali, & persetujuan wali (wajib) | G18: Belum Diuji
A19: 18 | F19: Pengguna ≥ 18 tahun: field wali tidak muncul | G19: Belum Diuji
A20: 19 | F20: Submit berhasil → status "Menunggu Review" tampil; form terkunci/ditampilkan baca-saja | G20: Belum Diuji
A21: 20 | F21: Status Disetujui/Ditolak/Diblokir tampil benar; Ditolak menampilkan alasan & bisa mengajukan ulang (BR-028 versi creator bila ada) | G21: Belum Diuji
A22: 21 | F22: Foto KTP tersimpan di storage PRIVAT (tidak punya URL publik) | G22: Belum Diuji
A23: 22 | F23: Data pribadi (KTP, alamat, rekening) tidak terlihat di halaman publik / respons API publik | G23: Belum Diuji
A24: 23 | B24: Creator | C24: Kelola Desain | D24: /creator/designs | E24: Daftar semua desain milik creator. | F24: Semua desain tampil dengan thumbnail, judul, harga, dan status (Draft / Menunggu Review / Published / Ditolak) | G24: Belum Diuji
A25: 24 | F25: Desain Ditolak menampilkan alasan penolakan admin | G25: Belum Diuji
A26: 25 | F26: Klik desain membuka halaman detail yang benar | G26: Belum Diuji
A27: 26 | F27: Tombol "Upload Desain" membuka halaman upload; belum ada desain → state kosong | G27: Belum Diuji
A28: 27 | F28: Creator hanya melihat desainnya sendiri (tidak ada desain milik creator lain) | G28: Belum Diuji
A29: 28 | F29: Thumbnail tidak broken (URL storage R2 benar) | G29: Belum Diuji
A30: 29 | B30: Creator | C30: Detail Desain (Creator) | D30: /creator/designs/[id] | E30: Detail, preview per apparel, konfirmasi, dan submit untuk approval. | F30: Info desain (gambar, judul, deskripsi, kategori, tag, status) benar | G30: Belum Diuji
A31: 30 | F31: Preview desain pada tiap produk/apparel yang dipilih tampil benar | G31: Belum Diuji
A32: 31 | F32: Tombol "Konfirmasi Preview" per produk berfungsi → badge "Terkonfirmasi" | G32: Belum Diuji
A33: 32 | F33: "Submit untuk Approval" hanya aktif bila preview sudah dikonfirmasi; status berubah "Menunggu Review" | G33: Belum Diuji
A34: 33 | F34: Desain Ditolak dapat direvisi (edit judul/deskripsi/file/produk) lalu disubmit ulang sebagai entri yang SAMA (BR-028) | G34: Belum Diuji
A35: 34 | F35: Edit desain: judul wajib (≤150), file opsional (PNG/SVG ≤20MB), minimal 1 produk, tag ≤10 (masing-masing ≤30 karakter) | G35: Belum Diuji
A36: 35 | F36: Desain milik creator lain → 404 / "Desain tidak ditemukan" | G36: Belum Diuji
A37: 36 | F37: Desain yang sudah published tidak bisa disubmit ulang secara keliru | G37: Belum Diuji
A38: 37 | B38: Creator | C38: Upload Desain | D38: /creator/designs/upload | E38: Mengunggah desain baru ke marketplace. | F38: Dropzone file: hanya PNG/SVG ≤ 20MB; format lain / terlalu besar ditolak dengan pesan jelas | G38: Belum Diuji
A39: 38 | F39: Submit tanpa file → "Pilih file desain terlebih dahulu"; tanpa apparel → "Pilih minimal satu jenis apparel" | G39: Belum Diuji
A40: 39 | F40: Judul wajib (≤150); deskripsi & kategori opsional | G40: Belum Diuji
...

Sheet Admin
A1: No | B1: Modul | C1: Halaman / Fitur | D1: URL / Path | E1: Deskripsi Halaman/Fitur | F1: Poin yang Diuji | G1: Hasil | H1: Catatan Tester
A2: 1 | B2: Admin | C2: Sidebar, Header & Akses Area Admin | D2: /admin/* | E2: Navigasi admin & pembatasan akses role admin. | F2: Sidebar 4 grup (Manajemen, Operasional, Komunikasi, Laporan) memuat 12 menu + Dashboard + Keluar; semua mengarah benar | G2: Belum Diuji
A3: 2 | F3: Customer/creator membuka /admin/* ditolak (pesan "Anda tidak memiliki akses") & API mengembalikan 403 | G3: Belum Diuji
A4: 3 | F4: Guest membuka /admin/* diarahkan ke login | G4: Belum Diuji
A5: 4 | F5: Header admin menampilkan label Admin, nama, notifikasi; logout dengan konfirmasi | G5: Belum Diuji
A6: 5 | F6: Di mobile sidebar menjadi drawer; tabel dapat digulir horizontal (tidak terpotong) | G6: Belum Diuji
A7: 6 | B7: Admin | C7: Dashboard Admin | D7: /admin/dashboard | E7: Ringkasan operasional. | F7: 8 kartu statistik (Menunggu Approval, Total Pendapatan, Total Customer, Desain Menunggu Approval, Diproses Produksi, Dikirim, Selesai, Creator Aktif) benar & tidak tertukar | G7: Belum Diuji
A8: 7 | F8: Total pendapatan hanya menghitung pesanan yang sudah dibayar/valid, format Rupiah benar | G8: Belum Diuji
A9: 8 | F9: Callout "Perlu Perhatian" menyebut jumlah pesanan/desain/creator pending yang benar & tautannya berfungsi | G9: Belum Diuji
A10: 9 | F10: Angka berubah setelah aksi admin (approve, mulai produksi) tanpa data usang | G10: Belum Diuji
A11: 10 | F11: Loading skeleton & error state tampil sesuai kondisi | G11: Belum Diuji
A12: 11 | B12: Admin | C12: Kelola User & Creator | D12: /admin/users | E12: Tabel semua pengguna. | F12: Tabel menampilkan nama, email, role, status (badge hijau aktif / merah lainnya) dengan benar | G12: Belum Diuji
A13: 12 | F13: Paginasi berfungsi (halaman sebelumnya/berikutnya, info "Halaman x dari y") | G13: Belum Diuji
A14: 13 | F14: Filter role/status via API (?role=&status=) bekerja bila dipakai | G14: Belum Diuji
A15: 14 | F15: Belum ada pengguna → state kosong | G15: Belum Diuji
A16: 15 | F16: Data sensitif (password, token) tidak tampil | G16: Belum Diuji
A17: 16 | B17: Admin | C17: Approval Creator & Blokir Creator | D17: /admin/creators/approval | E17: Review pengajuan creator, serta daftar creator aktif untuk diblokir (BR-001/008/019/020/023). | F17: Daftar pengajuan pending tampil lengkap: nama/brand, email, nama KYC, nomor KTP, tgl lahir, alamat, metode pencairan, badge "Di bawah 18 tahun", data wali bila ada | G17: Belum Diuji
A18: 17 | F18: "Lihat Foto KTP" membuka gambar KTP (bukan 404/403); hanya admin yang bisa melihat | G18: Belum Diuji
A19: 18 | F19: "Setujui" → creator aktif, notifikasi "creator.approved" terkirim, hilang dari daftar pending, muncul di "Creator Aktif" | G19: Belum Diuji
A20: 19 | F20: "Tolak" membuka modal alasan (min 10 karakter, bukan pop-up browser); tombol aktif hanya bila alasan cukup; tersimpan & notifikasi terkirim | G20: Belum Diuji
A21: 20 | F21: Menyetujui/menolak pengajuan yang statusnya sudah berubah ditolak dengan pesan yang jelas | G21: Belum Diuji
A22: 21 | F22: Bagian "Creator Aktif" menampilkan semua creator berstatus aktif dengan tombol "Blokir"; kosong → "Belum ada creator aktif" | G22: Belum Diuji
A23: 22 | F23: "Blokir" membuka modal: alasan (min 10 karakter) + centang "Pelanggaran hak cipta terbukti" + penjelasan konsekuensi | G23: Belum Diuji
A24: 23 | F24: Blokir biasa (tanpa centang): status creator banned, desainnya ditarik dari marketplace (BR-019), akun Customer TIDAK disuspend, komisi TIDAK ditahan | G24: Belum Diuji
A25: 24 | F25: Blokir pelanggaran hak cipta (centang): akun user disuspend/banned (tidak bisa login — BR-023) & semua komisi terhutang ditahan (BR-020) | G25: Belum Diuji
A26: 25 | F26: Pesanan yang sudah checkout sebelum blokir tetap diproduksi & dikirim normal (BR-019) | G26: Belum Diuji
A27: 26 | F27: Creator terblokir hilang dari daftar "Creator Aktif", dari marketplace, dan profil publiknya tidak dapat diakses | G27: Belum Diuji
A28: 27 | F28: Notifikasi "Akun Creator diblokir" + alasan terkirim ke creator; aksi tercatat di Audit Log | G28: Belum Diuji
A29: 28 | F29: Tidak ada pembatalan blokir lewat UI (konfirmasi perilaku ini diketahui; blokir bersifat final lewat aplikasi) | G29: Belum Diuji
A30: 29 | B30: Admin | C30: Approval Desain | D30: /admin/designs/approval | E30: Review desain sebelum tayang (BR-002). | F30: Daftar desain pending dengan preview gambar, judul, creator, produk terpilih, tag | G30: Belum Diuji
A31: 30 | F31: "Setujui" → desain published & langsung muncul di Marketplace publik; notifikasi "design.approved" terkirim | G31: Belum Diuji
A32: 31 | F32: "Tolak" membuka modal alasan (min 10) → status Ditolak + alasan terlihat oleh creator + notifikasi terkirim | G32: Belum Diuji
A33: 32 | F33: Desain yang sudah diputuskan tidak bisa diputuskan lagi (pesan error jelas) | G33: Belum Diuji
A34: 33 | F34: Kosong → "Belum ada desain menunggu review" | G34: Belum Diuji
A35: 34 | F35: Gambar/SVG tampil aman (tanpa eksekusi script) | G35: Belum Diuji
A36: 35 | B36: Admin | C36: Kelola Product Catalog — Produk | D36: /admin/catalog | E36: Kelola produk blanko (CRUD produk). | F36: Tabel produk menampilkan SEMUA produk termasuk NONAKTIF (badge "Nonaktif"): nama (ID), kategori, harga dasar | G36: Belum Diuji
A37: 36 | F37: "Tambah Produk": nama ID & EN wajib (≤150), harga dasar ≥ 0 wajib, segmen opsional, deskripsi ID/EN opsional, aktif | G37: Belum Diuji
A38: 37 | F38: Buka baris produk → form "Detail Produk" terisi (nama ID/EN, harga, segmen, deskripsi ID/EN, status aktif) | G38: Belum Diuji
A39: 38 | F39: Ubah data lalu "Simpan Perubahan" → toast sukses & tabel ter-update; refresh tetap tersimpan | G39: Belum Diuji
A40: 39 | F40: Menonaktifkan produk → hilang dari katalog publik; item di keranjang ditandai tidak tersedia; checkout ditolak | G40: Belum Diuji
...

Sheet Fitur Lintas Halaman (Umum)
A1: No | B1: Modul | C1: Halaman / Fitur | D1: URL / Path | E1: Deskripsi Halaman/Fitur | F1: Poin yang Diuji | G1: Hasil | H1: Catatan Tester
A2: 1 | B2: Fitur Lintas Halaman (Umum) | C2: Navbar & Role-based Access | D2: Semua halaman | E2: Navbar mengikuti status login; akses dibatasi sesuai role. | F2: Guest membuka halaman customer/creator/admin diarahkan ke login (dengan modal) tanpa kilatan konten privat | G2: Belum Diuji
A3: 2 | F3: Customer membuka /admin atau /creator ditolak; creator membuka /admin ditolak | G3: Belum Diuji
A4: 3 | F4: Akun admin membuka area customer (/account) berfungsi sesuai perilaku yang dirancang | G4: Belum Diuji
A5: 4 | F5: Logout (dengan dialog konfirmasi) berhasil keluar, sesi server berakhir & kembali ke beranda | G5: Belum Diuji
A6: 5 | F6: Setelah sesi kedaluwarsa (419/401) UI tidak macet — diarahkan/di-prompt login ulang | G6: Belum Diuji
A7: 6 | F7: Banned user langsung ditolak pada request berikutnya | G7: Belum Diuji
A8: 7 | B8: Fitur Lintas Halaman (Umum) | C8: Ganti Bahasa (Indonesia/English) | D8: Semua halaman | E8: Saklar bahasa ID/EN (cookie NEXT_LOCALE). | F8: Ganti bahasa mengubah semua teks di halaman tanpa flicker berlebihan; atribut <html lang> ikut berubah | G8: Belum Diuji
A9: 8 | F9: Pilihan bahasa persisten saat berpindah halaman, refresh, dan membuka tab baru | G9: Belum Diuji
A10: 9 | F10: Konten dinamis dari API (nama produk, deskripsi, kategori) mengikuti bahasa (header Accept-Language) | G10: Belum Diuji
A11: 10 | F11: Mode EN: telusuri satu halaman tiap role — TIDAK boleh ada teks Indonesia tersisa pada UI (catat setiap temuan) | G11: Belum Diuji
A12: 11 | F12: Mode ID: tidak ada teks Inggris yang bocor / key terjemahan mentah (mis. admin.catalog.xxx) tampil | G12: Belum Diuji
A13: 12 | F13: Pesan error validasi dari backend mengikuti bahasa; email verifikasi/reset mengikuti bahasa | G13: Belum Diuji
A14: 13 | F14: Notifikasi yang dihasilkan sistem (mis. dibatalkan otomatis) — catat bahwa masih berbahasa Indonesia (gap diketahui) | G14: Belum Diuji
A15: 14 | F15: Format tanggal & angka/Rupiah sesuai locale | G15: Belum Diuji
A16: 15 | B16: Fitur Lintas Halaman (Umum) | C16: Tampilan Responsif | D16: Semua halaman | E16: Tampilan di berbagai ukuran layar (breakpoint md 768 / lg 1024). | F16: Mobile (375px & 360px): tidak ada elemen terpotong, tumpang tindih, atau scroll horizontal tak disengaja | G16: Belum Diuji
A17: 16 | F17: Tablet (768px) & desktop (1280/1920px): tata letak rapi & konsisten | G17: Belum Diuji
A18: 17 | F18: Navbar jadi hamburger + drawer di bawah md; sidebar akun/creator/admin jadi drawer di bawah lg | G18: Belum Diuji
A19: 18 | F19: Grid produk/desain: 5 kolom desktop → 3 tablet → 2 mobile | G19: Belum Diuji
A20: 19 | F20: Layout 2-kolom (Cart, Checkout, Detail Pesanan, Invoice): ringkasan turun ke bawah di mobile; CTA tetap terjangkau | G20: Belum Diuji
A21: 20 | F21: Tabel admin dapat digulir horizontal di mobile | G21: Belum Diuji
A22: 21 | F22: Modal (login, ban, tolak, konfirmasi) muat di layar kecil & dapat digulir | G22: Belum Diuji
A23: 22 | F23: Orientasi portrait ↔ landscape tidak merusak layout | G23: Belum Diuji
A24: 23 | F24: Zoom browser 50%–200% tidak merusak layout utama | G24: Belum Diuji
A25: 24 | B25: Fitur Lintas Halaman (Umum) | C25: Kompatibilitas Browser & Perangkat | D25: Semua halaman | E25: Uji lintas browser/perangkat. | F25: Chrome (Windows & Android) versi terbaru: semua alur utama berjalan | G25: Belum Diuji
A26: 25 | F26: Firefox versi terbaru berjalan | G26: Belum Diuji
A27: 26 | F27: Safari (macOS & iOS) berjalan — cookie sesi, upload file, dan modal berfungsi | G27: Belum Diuji
A28: 27 | F28: Edge berjalan | G28: Belum Diuji
A29: 28 | F29: Cookie pihak pertama: login tetap bekerja walau third-party cookie diblokir | G29: Belum Diuji
A30: 29 | F30: Mode incognito/private: login, keranjang, & checkout berfungsi | G30: Belum Diuji
A31: 30 | F31: Koneksi lambat (Fast 3G): halaman tetap dapat dipakai, skeleton tampil, tidak ada timeout diam-diam | G31: Belum Diuji
A32: 31 | F32: JavaScript nonaktif: halaman publik utama tetap menampilkan konten dasar (SSR) atau pesan yang sesuai | G32: Belum Diuji
A33: 32 | B33: Fitur Lintas Halaman (Umum) | C33: Aksesibilitas & Keyboard | D33: Semua halaman | E33: Dasar aksesibilitas. | F33: Navigasi keyboard (Tab/Shift+Tab/Enter/Esc) dapat menjalankan alur utama; fokus terlihat jelas | G33: Belum Diuji
A34: 33 | F34: Modal mengunci fokus & Esc menutup; fokus kembali ke pemicu setelah ditutup | G34: Belum Diuji
A35: 34 | F35: Semua gambar bermakna punya teks alternatif; tombol ikon punya label (aria-label) | G35: Belum Diuji
A36: 35 | F36: Kontras warna teks memadai (terutama teks di atas tombol hijau/aksen) | G36: Belum Diuji
A37: 36 | F37: Form: label terhubung dengan input; pesan error terbaca screen reader | G37: Belum Diuji
A38: 37 | B38: Fitur Lintas Halaman (Umum) | C38: Toast, Dialog & Komponen UI Bersama | D38: Semua halaman | E38: Komponen bersama. | F38: Toast sukses/gagal muncul, dapat ditutup, hilang otomatis, tidak menumpuk berlebihan | G38: Belum Diuji
A39: 38 | F39: Dialog konfirmasi (logout, dll): Batal vs Konfirmasi bekerja benar | G39: Belum Diuji
A40: 39 | F40: Pagination: tombol Sebelumnya/Berikutnya nonaktif di ujung; info halaman benar | G40: Belum Diuji
...

Sheet Halaman Error & Edge
A1: No | B1: Modul | C1: Halaman / Fitur | D1: URL / Path | E1: Deskripsi Halaman/Fitur | F1: Poin yang Diuji | G1: Hasil | H1: Catatan Tester
A2: 1 | B2: Halaman Error & Edge | C2: Halaman 404 (not-found) | D2: /url-ngawur, /catalog/slug-tak-ada | E2: Halaman tidak ditemukan global (app/not-found.tsx). | F2: Membuka URL acak (mis. /asdf) menampilkan halaman "Halaman Tidak Ditemukan" dengan ilustrasi (bukan halaman putih/default Next.js) | G2: Belum Diuji
A3: 2 | F3: Tombol "Kembali ke Beranda" → /; tombol "Lihat Katalog Produk" → /catalog | G3: Belum Diuji
A4: 3 | F4: 404 tampil dengan header & footer yang benar; tidak ada error di console | G4: Belum Diuji
A5: 4 | F5: 404 menampilkan bahasa sesuai pilihan (ID/EN); judul tab sesuai | G5: Belum Diuji
A6: 5 | F6: Rute lama berbahasa Indonesia sebelum rename (mis. /katalog-produk, /lapak-desain, /keranjang, /pesanan) menghasilkan 404 bersih (bukan error) | G6: Belum Diuji
A7: 6 | F7: Slug dinamis tidak ada: /catalog/xxx, /marketplace/xxx, /marketplace/design/xxx → pesan "tidak ditemukan" khusus + tombol kembali (bukan crash) | G7: Belum Diuji
A8: 7 | F8: ID dinamis tidak ada: /account/orders/99999, /creator/designs/99999 → pesan "tidak ditemukan" (bukan crash) | G8: Belum Diuji
A9: 8 | F9: URL dengan karakter aneh/sangat panjang (%00, <script>, 5000 karakter) → 404/400 yang aman, tanpa error server | G9: Belum Diuji
A10: 9 | F10: Status HTTP respons 404 benar (bukan 200 dengan isi 404) untuk halaman tak ada | G10: Belum Diuji
A11: 10 | F11: File statis tak ada (/gambar-tak-ada.png) → 404 biasa | G11: Belum Diuji
A12: 11 | B12: Halaman Error & Edge | C12: Error Boundary Rute (error.tsx) | D12: Tiap area: publik, auth, customer, creator, admin | E12: Halaman saat terjadi error runtime di sebuah area (error.tsx per route-group). | F12: Simulasikan error render (mis. matikan backend lalu buka halaman data / paksa throw di dev) di area PUBLIK → tampil ErrorState "Terjadi kesalahan" + tombol "Coba Lagi", header/footer tetap | G12: Belum Diuji
A13: 12 | F13: Hal yang sama pada area AUTH (/reset-password, /verify-email) | G13: Belum Diuji
A14: 13 | F14: Hal yang sama pada area CUSTOMER (keranjang, checkout, pesanan, akun) | G14: Belum Diuji
A15: 14 | F15: Hal yang sama pada area CREATOR | G15: Belum Diuji
A16: 15 | F16: Hal yang sama pada area ADMIN (sidebar tetap berfungsi) | G16: Belum Diuji
A17: 16 | F17: Tombol "Coba Lagi" memuat ulang bagian yang error & pulih bila masalah sudah selesai | G17: Belum Diuji
A18: 17 | F18: Error tidak membocorkan stack trace/detail internal ke pengguna | G18: Belum Diuji
A19: 18 | F19: Error dicatat di console/log tanpa membuat loop render tak terbatas | G19: Belum Diuji
A20: 19 | B20: Halaman Error & Edge | C20: Root Error Boundary (error.tsx root) | D20: Semua | E20: Fallback terakhir saat layout root gagal (tanpa i18n — berbahasa Inggris). | F20: Saat layout/root provider gagal, tampil "Something went wrong" + tombol "Try Again" (dependency-free) — bukan layar putih | G20: Belum Diuji
A21: 20 | F21: "Try Again" memulihkan halaman bila penyebab sudah hilang | G21: Belum Diuji
A22: 21 | F22: Fallback ini tampil rapi di mobile & desktop (catat: teks Inggris saja, gap diketahui) | G22: Belum Diuji
A23: 22 | B23: Halaman Error & Edge | C23: Backend Mati / Jaringan Putus | D23: Seluruh aplikasi | E23: Perilaku frontend saat API tidak tersedia (laptop/tunnel mati → 502/500). | F23: Matikan backend: halaman publik berdata (katalog, marketplace, beranda) menampilkan error state yang ramah, bukan crash/blank | G23: Belum Diuji
A24: 23 | F24: Aksi tulis (tambah keranjang, checkout, kirim chat) saat offline menampilkan toast/pesan error & tombol kembali aktif (tidak loading selamanya) | G24: Belum Diuji
A25: 24 | F25: Respons 502/503/504 dari Cloudflare/tunnel tidak menampilkan JSON mentah ke pengguna | G25: Belum Diuji
A26: 25 | F26: Setelah backend hidup kembali, aplikasi pulih tanpa harus menghapus cookie (retry/refresh cukup) | G26: Belum Diuji
A27: 26 | F27: Putus internet di browser (mode pesawat): pesan wajar, tidak ada exception tak tertangani di console | G27: Belum Diuji
A28: 27 | F28: Backend hidup tapi MySQL mati: respons 500 ditangani sama baiknya; tidak membocorkan kredensial DB | G28: Belum Diuji
A29: 28 | F29: Request lambat/timeout: ada indikator loading & tidak ada klik ganda yang menggandakan aksi | G29: Belum Diuji
A30: 29 | B30: Halaman Error & Edge | C30: Sesi & Otentikasi Bermasalah | D30: Seluruh aplikasi | E30: 401/403/419. | F30: Sesi kedaluwarsa saat di halaman terproteksi (hapus cookie sesi) → aplikasi meminta login ulang tanpa blank/loop redirect | G30: Belum Diuji
A31: 30 | F31: CSRF token mismatch (419) ditangani: aplikasi mengambil ulang cookie CSRF & mengulang/menampilkan pesan, bukan crash | G31: Belum Diuji
A32: 31 | F32: 403 saat customer menembak endpoint admin → pesan akses ditolak yang jelas | G32: Belum Diuji
A33: 32 | F33: 401 pada panggilan API di tengah sesi → UI keluar ke state guest dengan benar | G33: Belum Diuji
A34: 33 | F34: Login di dua tab/perangkat; logout di satu tab → tab lain terdeteksi saat aksi berikutnya | G34: Belum Diuji
A35: 34 | F35: Akun di-ban saat sedang login → aksi berikutnya ditolak & user dikeluarkan | G35: Belum Diuji
A36: 35 | B36: Halaman Error & Edge | C36: Status HTTP & Pesan Error API (UI) | D36: Seluruh aplikasi | E36: Penanganan kode status di UI. | F36: 422 validasi: pesan per-field tampil di form terkait (bahasa sesuai) | G36: Belum Diuji
A37: 36 | F37: 409 konflik (mis. menolak pesanan yang sudah berubah) ditampilkan sebagai pesan jelas | G37: Belum Diuji
A38: 37 | F38: 429 terlalu banyak percobaan (login/auth) ditampilkan dengan pesan yang dimengerti | G38: Belum Diuji
A39: 38 | F39: 404 pada resource milik orang lain tampil sebagai "tidak ditemukan" | G39: Belum Diuji
A40: 39 | F40: 500 tak terduga ditampilkan sebagai pesan umum "Terjadi kesalahan, coba lagi" tanpa detail teknis | G40: Belum Diuji
...

Sheet Validasi Form & API
A1: No | B1: Modul | C1: Halaman / Fitur | D1: URL / Path | E1: Deskripsi Halaman/Fitur | F1: Poin yang Diuji | G1: Hasil | H1: Catatan Tester
A2: 1 | B2: Validasi Form & API | C2: Form Login & Registrasi | D2: Modal Auth | E2: Batas validasi (LoginRequest, RegisterRequest). | F2: Login: email kosong → ditolak; password kosong → ditolak; email format salah → ditolak | G2: Belum Diuji
A3: 2 | F3: Register: nama kosong / 151 karakter → ditolak; 150 karakter → lulus | G3: Belum Diuji
A4: 3 | F4: Register: email > 255 karakter / format salah / sudah terdaftar → ditolak | G4: Belum Diuji
A5: 4 | F5: Register: password 7 karakter → ditolak; 8 karakter → lulus; konfirmasi berbeda → ditolak | G5: Belum Diuji
A6: 5 | F6: Register: tanpa centang privacy_accepted / terms_accepted → ditolak | G6: Belum Diuji
A7: 6 | F7: Spasi di awal/akhir email ditangani; email huruf besar/kecil diperlakukan konsisten | G7: Belum Diuji
A8: 7 | B8: Validasi Form & API | C8: Form Profil & Alamat | D8: /account/profile, /account/addresses | E8: UpdateProfileRequest, AddressRequest. | F8: Profil: nama kosong/>150 → ditolak; telepon >20 → ditolak; telepon kosong → lulus (opsional) | G8: Belum Diuji
A9: 8 | F9: Alamat: label kosong/>50 → ditolak; penerima kosong/>150; telepon kosong/>20 | G9: Belum Diuji
A10: 9 | F10: Alamat: provinsi/kota/kecamatan kosong atau >100 → ditolak | G10: Belum Diuji
A11: 10 | F11: Alamat: kode pos kosong/>10 karakter → ditolak; alamat lengkap kosong → ditolak | G11: Belum Diuji
A12: 11 | F12: Alamat: is_default hanya boolean; menetapkan alamat baru sebagai default menurunkan default lama | G12: Belum Diuji
A13: 12 | B13: Validasi Form & API | C13: Form Pengajuan Creator & KYC | D13: /account/become-creator, /creator/verification | E13: CreatorApplicationRequest, CreatorVerificationRequest. | F13: Pengajuan: brand >150 / bio >500 / portofolio bukan URL / >255 → ditolak; tanpa terms → ditolak | G13: Belum Diuji
A14: 13 | F14: KYC: nama KYC kosong/>150; nomor KTP kosong/>100; alamat kosong/>500 | G14: Belum Diuji
A15: 14 | F15: KYC: tanggal lahir kosong / hari ini / masa depan → ditolak; kemarin → lulus | G15: Belum Diuji
A16: 15 | F16: KYC: foto KTP kosong; PDF/GIF ditolak; JPG & PNG ≤5MB lulus; 5,1MB ditolak | G16: Belum Diuji
A17: 16 | F17: KYC: metode pencairan di luar {bank_transfer, gopay, ovo, dana, shopeepay} ditolak | G17: Belum Diuji
A18: 17 | F18: KYC: nomor rekening kosong/>50; nama pemilik kosong/>150 | G18: Belum Diuji
A19: 18 | F19: KYC pengguna <18 tahun tanpa data wali/persetujuan wali → ditolak | G19: Belum Diuji
A20: 19 | B20: Validasi Form & API | C20: Form Desain Creator | D20: /creator/designs/upload, edit | E20: CreatorDesignRequest, CreatorDesignUpdateRequest. | F20: Judul kosong/>150 → ditolak; deskripsi opsional; kategori harus ada di database | G20: Belum Diuji
A21: 20 | F21: File: wajib saat buat; PNG & SVG ≤20MB lulus; JPG/GIF/PDF ditolak; 20,1MB ditolak | G21: Belum Diuji
A22: 21 | F22: product_ids: kosong → ditolak; id tidak ada → ditolak; satu id valid → lulus | G22: Belum Diuji
A23: 22 | F23: Tag: 10 tag lulus, 11 ditolak; satu tag 31 karakter ditolak | G23: Belum Diuji
A24: 23 | F24: Edit: file opsional; judul & product_ids tetap wajib | G24: Belum Diuji
A25: 24 | B25: Validasi Form & API | C25: Form Katalog Admin | D25: /admin/catalog | E25: ProductRequest, ProductVariantRequest, BulkPricingTierRequest, UploadMockupFileRequest. | F25: Produk: nama ID/EN kosong/>150 ditolak; harga kosong/negatif/bukan angka ditolak; harga 0 lulus | G25: Belum Diuji
A26: 25 | F26: Produk: segmen di luar {pria, wanita, unisex, anak} ditolak; kategori tidak ada ditolak | G26: Belum Diuji
A27: 26 | F27: Varian: warna >50, ukuran >20, potongan >50, material >100 ditolak; area cetak di luar {depan, belakang, lengan} ditolak | G27: Belum Diuji
A28: 27 | F28: Varian: tambahan harga bukan angka ditolak; negatif lulus; mockup kosong ditolak | G28: Belum Diuji
A29: 28 | F29: Mockup: PNG/SVG ≤20MB lulus; format lain ditolak | G29: Belum Diuji
A30: 29 | F30: Tier Bulk: min_qty <1 / bukan bilangan bulat ditolak; max_qty < min_qty ditolak; harga negatif ditolak | G30: Belum Diuji
A31: 30 | B31: Validasi Form & API | C31: Form Keranjang, Checkout & Ongkir | D31: /cart, /checkout, /checkout/bulk | E31: CartItemRequest, UpdateCartItemRequest, CheckoutRequest, BulkCheckoutRequest, ShippingRateRequest. | F31: Keranjang: product_variant_id tidak ada → ditolak; quantity 0/negatif/desimal → ditolak; qty 1 lulus (BR-009) | G31: Belum Diuji
A32: 31 | F32: Checkout: cart_item_ids kosong → ditolak; id milik user lain → ditolak; address_id milik user lain/ tak ada → ditolak | G32: Belum Diuji
A33: 32 | F33: Checkout: courier_company/courier_type kosong atau >50 → ditolak; kurir yang tidak tersedia untuk alamat → ditolak (bukan ongkir 0) | G33: Belum Diuji
A34: 33 | F34: Bulk: items kosong ditolak; item qty <1 ditolak; varian tak ada ditolak; design_id tak ada ditolak | G34: Belum Diuji
A35: 34 | F35: Ongkir (shipping-rates): wajib address_id + salah satu dari cart_item_ids / items | G35: Belum Diuji
A36: 35 | F36: Catatan (notes) panjang & karakter khusus tersimpan aman | G36: Belum Diuji
A37: 36 | B37: Validasi Form & API | C37: Form Ulasan, Chat, Wishlist, Alasan | D37: Detail pesanan, chat, wishlist, modal admin | E37: ReviewRequest, ChatMessageRequest, WishlistRequest, ReasonRequest, BanCreatorRequest. | F37: Ulasan: rating 0/6/kosong ditolak; 1–5 lulus; order_item bukan milik user ditolak; komentar opsional | G37: Belum Diuji
A38: 37 | F38: Chat: pesan kosong / 2001 karakter ditolak; 2000 lulus | G38: Belum Diuji
A39: 38 | F39: Wishlist: harus salah satu dari product_id atau design_id; keduanya kosong ditolak; id tak ada ditolak | G39: Belum Diuji
A40: 39 | F40: Alasan tolak/ban: kurang dari 10 karakter ditolak (UI menonaktifkan tombol); 10 karakter lulus | G40: Belum Diuji
...

Sheet Aturan Bisnis (BR)
A1: No | B1: Modul | C1: Halaman / Fitur | D1: URL / Path | E1: Deskripsi Halaman/Fitur | F1: Poin yang Diuji | G1: Hasil | H1: Catatan Tester
A2: 1 | B2: Aturan Bisnis (BR) | C2: BR-001 / BR-002 / BR-008 Approval creator & desain | D2: Aturan bisnis | E2: Creator & desain wajib approval admin; creator wajib KYC. | F2: Customer biasa tidak bisa mengakses endpoint upload desain (403) | G2: Belum Diuji
A3: 2 | F3: Creator berstatus menunggu approval tidak bisa upload desain sampai disetujui | G3: Belum Diuji
A4: 3 | F4: Desain baru tidak tampil publik sebelum approval admin | G4: Belum Diuji
A5: 4 | F5: Creator tidak bisa diaktifkan tanpa data KYC lengkap (validasi KTP, tanggal lahir, rekening) | G5: Belum Diuji
A6: 5 | B6: Aturan Bisnis (BR) | C6: BR-003 Pembayaran sebelum produksi | D6: Aturan bisnis | E6: Pesanan masuk produksi hanya setelah Midtrans konfirmasi. | F6: Pesanan Belum Dibayar tidak muncul di Antrian Produksi & tidak bisa di-"Mulai Produksi" | G6: Belum Diuji
A7: 6 | F7: Status berubah ke Menunggu Approval hanya lewat webhook Midtrans valid (status diverifikasi ulang server-ke-server) | G7: Belum Diuji
A8: 7 | B8: Aturan Bisnis (BR) | C8: BR-004 Rating setelah Selesai | D8: Aturan bisnis | E8: Ulasan hanya setelah Selesai. | F8: Form rating tidak muncul/ditolak API sebelum status Selesai | G8: Belum Diuji
A9: 8 | F9: Selesai karena konfirmasi manual: form langsung tampil; karena auto-complete: tetap tersedia dari riwayat | G9: Belum Diuji
A10: 9 | F10: Satu item hanya dapat diulas sekali; ulasan hanya oleh pemilik pesanan | G10: Belum Diuji
A11: 10 | B11: Aturan Bisnis (BR) | C11: BR-005 Desain hanya lewat cetak | D11: Aturan bisnis | E11: Desain creator tidak dijual sebagai file digital. | F11: Tidak ada tombol/endpoint untuk mengunduh file asli desain creator oleh customer | G11: Belum Diuji
A12: 11 | F12: URL file asli desain tidak terekspos lewat respons API publik selain yang dibutuhkan (thumbnail) | G12: Belum Diuji
A13: 12 | B13: Aturan Bisnis (BR) | C13: BR-006 / BR-015 Refund manual | D13: Aturan bisnis | E13: Refund ditangani manual admin. | F13: Tidak ada tombol refund otomatis; alur refund (via chat + proses manual admin) terdokumentasi di Kebijakan Retur & Refund | G13: Belum Diuji
A14: 13 | F14: Produksi gagal total: admin menawarkan alternatif bahan/warna via Chat sebelum refund penuh | G14: Belum Diuji
A15: 14 | B15: Aturan Bisnis (BR) | C15: BR-007 Komisi creator & payout | D15: Aturan bisnis | E15: Komisi otomatis, payout otomatis mingguan. | F15: Komisi tercipta otomatis per item pesanan yang memakai desain creator saat pesanan dibayar (bukan untuk custom upload) | G15: Belum Diuji
A16: 15 | F16: Nominal = persentase (CREATOR_COMMISSION_RATE) × subtotal item | G16: Belum Diuji
A17: 16 | F17: Payout mingguan hanya untuk total terhutang ≥ CREATOR_PAYOUT_MINIMUM & rekening terisi | G17: Belum Diuji
A18: 17 | F18: Komisi baru berstatus "Dibayar" setelah transfer terkonfirmasi (provider disbursement) — tidak ditandai dibayar tanpa transfer | G18: Belum Diuji
A19: 18 | F19: Persentase & minimum payout yang dipakai produksi sudah diputuskan pemilik (saat ini placeholder 20% / Rp 50.000) | G19: Belum Diuji
A20: 19 | B20: Aturan Bisnis (BR) | C20: BR-009 Tanpa minimum order | D20: Aturan bisnis | E20: Pemesanan 1 pcs dilayani. | F20: Checkout reguler 1 pcs berhasil; qty 0/negatif ditolak | G20: Belum Diuji
A21: 20 | B21: Aturan Bisnis (BR) | C21: BR-010 / BR-018 / BR-022 Pembatalan | D21: Aturan bisnis | E21: Batal hanya saat Menunggu Approval, per-order, bulk all-or-nothing. | F21: Batal diizinkan hanya status Menunggu Approval; status lain → 422 | G21: Belum Diuji
A22: 21 | F22: Tidak ada UI/endpoint batal per-item atau parsial; tidak ada pembayaran sebagian (DP) | G22: Belum Diuji
A23: 22 | B23: Aturan Bisnis (BR) | C23: BR-011 / BR-016 Produksi ulang & komplain | D23: Aturan bisnis | E23: Kebijakan kualitas. | F23: Informasi produksi ulang gratis & masa komplain 7 hari tertulis konsisten di FAQ/Retur/Terms | G23: Belum Diuji
A24: 23 | B24: Aturan Bisnis (BR) | C24: BR-012 Harga Bulk bertingkat | D24: Aturan bisnis | E24: Tier berdasarkan total qty. | F24: Batas tier uji nilai tepi: qty = min tier, = maks tier, = maks+1, di bawah tier terendah (ditolak), di atas tier tertinggi | G24: Belum Diuji
A25: 24 | F25: Harga tier sama persis di halaman Bulk Order, Checkout Bulk, & tabel pesanan | G25: Belum Diuji
A26: 25 | B26: Aturan Bisnis (BR) | C26: BR-013 Akun creator = upgrade customer | D26: Aturan bisnis | E26: Satu akun, dua peran. | F26: Tidak ada registrasi creator terpisah; satu email = satu akun | G26: Belum Diuji
A27: 26 | F27: User creator tetap bisa belanja sebagai customer tanpa logout | G27: Belum Diuji
A28: 27 | B28: Aturan Bisnis (BR) | C28: BR-014 Status otomatis dari kurir | D28: Aturan bisnis | E28: Delivered → Menunggu Konfirmasi → Selesai. | F28: Webhook delivered → Menunggu Konfirmasi; konfirmasi manual → Selesai; tanpa konfirmasi 3 hari kerja → Selesai otomatis | G28: Belum Diuji
A29: 28 | B29: Aturan Bisnis (BR) | C29: BR-017 Auto-batal 24 jam | D29: Aturan bisnis | E29: Belum dibayar 24 jam dibatalkan. | F29: Job cancel-unpaid membatalkan tepat > 24 jam; nilai waktu dibaca dari config/business.php | G29: Belum Diuji
A30: 29 | F30: Pesanan yang dibatalkan menyimpan cancelled_by=system & riwayat status | G30: Belum Diuji
A31: 30 | B31: Aturan Bisnis (BR) | C31: BR-019 / BR-020 / BR-021 / BR-023 Blokir creator | D31: Aturan bisnis | E31: Dampak blokir. | F31: Lihat E2E-07 — semua skenario lulus | G31: Belum Diuji
A32: 31 | F32: Dispute plagiarisme tidak punya UI khusus; ditangani manual admin lewat chat/email (konfirmasi tidak ada UI yang menyesatkan) | G32: Belum Diuji
A33: 32 | B33: Aturan Bisnis (BR) | C33: BR-024 Wishlist item tidak tersedia | D33: Aturan bisnis | E33: Item tetap tampil dengan badge. | F33: Item wishlist yang produk/desainnya tidak lagi tersedia tetap muncul dengan badge "Tidak Tersedia" & tidak bisa dibeli; tidak terhapus otomatis | G33: Belum Diuji
A34: 33 | B34: Aturan Bisnis (BR) | C34: BR-025 Harga terkunci di keranjang | D34: Aturan bisnis | E34: Snapshot harga. | F34: Lihat E2E-09 — lulus | G34: Belum Diuji
A35: 34 | B35: Aturan Bisnis (BR) | C35: BR-026 Bulk dan reguler terpisah | D35: Aturan bisnis | E35: Tidak boleh digabung. | F35: Endpoint /checkout tidak pernah memakai harga tier; /checkout/bulk tidak memakai keranjang | G35: Belum Diuji
A36: 35 | F36: Item reguler di keranjang tidak ikut ter-checkout pada Bulk Order | G36: Belum Diuji
A37: 36 | B37: Aturan Bisnis (BR) | C37: BR-027 Notifikasi in-app saja (real-time) | D37: Aturan bisnis | E37: Tanpa email/SMS untuk notifikasi pesanan. | F37: Notifikasi pesanan hanya in-app & real-time; tidak ada email status pesanan (hanya email verifikasi & reset password) | G37: Belum Diuji
A38: 37 | F38: Pengaturan admin mematikan jenis notifikasi tertentu efektif | G38: Belum Diuji
A39: 38 | B39: Aturan Bisnis (BR) | C39: BR-028 Revisi desain ditolak | D39: Aturan bisnis | E39: Revisi pada entri yang sama. | F39: Lihat E2E-08 — lulus | G39: Belum Diuji

Sheet Alur End-to-End
A1: No | B1: Modul | C1: Halaman / Fitur | D1: URL / Path | E1: Deskripsi Halaman/Fitur | F1: Poin yang Diuji | G1: Hasil | H1: Catatan Tester
A2: 1 | B2: Alur End-to-End | C2: E2E-01 Pembelian reguler lengkap (golden path) | D2: Guest → Selesai | E2: Dari pengunjung baru sampai pesanan selesai & diulas. | F2: Guest membuka beranda → katalog → detail produk; pilih warna/ukuran, upload desain sendiri, Tambah ke Keranjang → diminta login | G2: Belum Diuji
A3: 2 | F3: Registrasi akun baru (centang syarat & privasi) → email verifikasi tiba → klik tautan → "Email berhasil diverifikasi" | G3: Belum Diuji
A4: 3 | F4: Login → keranjang berisi item yang tadi ditambahkan (tidak hilang) | G4: Belum Diuji
A5: 4 | F5: Tambah alamat valid (kode pos nyata) di Address Book → jadikan utama | G5: Belum Diuji
A6: 5 | F6: Keranjang → pilih item → Beli → Checkout: alamat otomatis terpilih, pilih kurir, ongkir muncul, total benar | G6: Belum Diuji
A7: 6 | F7: Buat Pesanan → Midtrans Snap → bayar (Sandbox) → kembali ke situs; status pesanan "Menunggu Approval"; notifikasi "pesanan dibayar"; invoice tersedia; pembayaran tercatat di admin | G7: Belum Diuji
A8: 7 | F8: Admin: Antrian Produksi melihat pesanan + pratinjau file desain → "Mulai Produksi" → customer melihat status "Diproses" | G8: Belum Diuji
A9: 8 | F9: Admin: Kelola Pengiriman → "Proses Pengiriman" → resi muncul; webhook Biteship "inTransit" → pesanan "Dikirim" + notifikasi "order.shipped" | G9: Belum Diuji
A10: 9 | F10: Webhook Biteship "delivered" → pesanan "Menunggu Konfirmasi" + notifikasi "order.delivered" | G10: Belum Diuji
A11: 10 | F11: Customer "Konfirmasi Diterima" → "Selesai"; form rating tampil → beri bintang & komentar → tersimpan; ulasan muncul di halaman produk | G11: Belum Diuji
A12: 11 | F12: Seluruh riwayat status (timeline) pada detail pesanan lengkap & berurutan; Audit Log admin mencatat aksi admin | G12: Belum Diuji
A13: 12 | B13: Alur End-to-End | C13: E2E-02 Desain creator → dibeli → komisi → pencairan | D13: Customer → Creator → Admin | E13: Alur marketplace dari upgrade creator sampai komisi. | F13: Customer ajukan upgrade creator → isi KYC (+ wali bila < 18 th) → status "Menunggu Review" | G13: Belum Diuji
A14: 13 | F14: Admin Approval Creator → Setujui → creator mendapat notifikasi; area /creator terbuka | G14: Belum Diuji
A15: 14 | F15: Creator upload desain (PNG/SVG, produk, tag) → konfirmasi preview → Submit untuk Approval | G15: Belum Diuji
A16: 15 | F16: Admin Approval Desain → Setujui → desain muncul di Marketplace & profil creator | G16: Belum Diuji
A17: 16 | F17: Customer lain membeli produk dengan desain tersebut (rincian harga: produk + kontribusi desainer) sampai pembayaran sukses | G17: Belum Diuji
A18: 17 | F18: Creator: Earnings menampilkan komisi "Terhutang" = persentase komisi × subtotal item | G18: Belum Diuji
A19: 18 | F19: Menjalankan `php artisan commissions:payout`: komisi di bawah minimum (Rp 50.000) TIDAK dicairkan; di atas minimum + ada rekening → diproses (catatan: disbursement masih stub — status tetap terhutang bila provider belum aktif) | G19: Belum Diuji
A20: 19 | F20: Creator tanpa data rekening dilewati dengan log peringatan (tidak error) | G20: Belum Diuji
A21: 20 | B21: Alur End-to-End | C21: E2E-03 Bulk Order end-to-end | D21: Customer → Admin | E21: Pemesanan jumlah besar harga bertingkat. | F21: Detail produk → "Pesan lewat Bulk Order" → isi qty beberapa ukuran; tier harga mengikuti TOTAL qty | G21: Belum Diuji
A22: 21 | F22: Lanjut Checkout Bulk → alamat, kurir → Buat Pesanan Bulk → bayar | G22: Belum Diuji
A23: 22 | F23: Pesanan bertipe bulk di admin; harga per unit sesuai tier; total benar | G23: Belum Diuji
A24: 23 | F24: Bulk Order dan keranjang reguler tidak bisa digabung dalam satu checkout (BR-026) | G24: Belum Diuji
A25: 24 | F25: Pembatalan Bulk Order bersifat penuh (BR-022) — tidak ada pembatalan parsial | G25: Belum Diuji
A26: 25 | B26: Alur End-to-End | C26: E2E-04 Pembatalan pesanan | D26: Customer / Sistem | E26: Semua jalur pembatalan. | F26: Customer membatalkan saat "Menunggu Approval" → Dibatalkan (BR-010); refund diproses manual admin (BR-006) | G26: Belum Diuji
A27: 26 | F27: Setelah "Diproses Produksi" tombol batal tidak ada & API menolak (422) | G27: Belum Diuji
A28: 27 | F28: Pesanan "Belum Dibayar" > 24 jam → otomatis Dibatalkan oleh `orders:cancel-unpaid` (jalankan manual untuk uji) + notifikasi (BR-017) | G28: Belum Diuji
A29: 28 | F29: Pesanan belum dibayar < 24 jam TIDAK dibatalkan oleh job | G29: Belum Diuji
A30: 29 | F30: Pembatalan hanya per-order, tidak per-item (BR-018) | G30: Belum Diuji
A31: 30 | B31: Alur End-to-End | C31: E2E-05 Penolakan pesanan oleh admin | D31: Admin → Customer | E31: Pesanan ditolak (mis. file desain tidak layak). | F31: Admin menolak pesanan "Menunggu Approval" dengan alasan ≥ 10 karakter → status Ditolak | G31: Belum Diuji
A32: 31 | F32: Customer menerima notifikasi berisi alasan; detail pesanan menampilkan "Pesanan Ditolak" + alasan | G32: Belum Diuji
A33: 32 | F33: Menolak pesanan yang statusnya sudah berubah → 409 Conflict (bukan 422) | G33: Belum Diuji
A34: 33 | F34: Refund dilakukan manual & dikomunikasikan lewat chat (BR-006/015) — alur manual terdokumentasi | G34: Belum Diuji
A35: 34 | B35: Alur End-to-End | C35: E2E-06 Auto-complete & masa komplain | D35: Sistem → Customer | E35: Penyelesaian otomatis & komplain. | F35: Pesanan "Menunggu Konfirmasi" tanpa konfirmasi: sebelum 3 hari kerja → TIDAK diselesaikan; setelah 3 hari kerja (Sen–Jum, akhir pekan tidak dihitung) → otomatis Selesai (BR-014) | G35: Belum Diuji
A36: 35 | F36: Notifikasi "otomatis diselesaikan" terkirim; rating tetap bisa diberikan belakangan lewat riwayat pesanan (BR-004) | G36: Belum Diuji
